<?xml version="1.0" encoding="UTF-8"?>
<robot generator="Robot 4.1 (Python 3.8.2 on darwin)" generated="20210802 17:10:26.757" rpa="false" schemaversion="2">
<suite id="s1" name="Login" source="/Users/oa1220/Documents/Projects/appium-framework/app/tests/login.robot">
<test id="s1-t1" name="Validate login page">
<kw name="When Launch application">
<msg timestamp="20210802 17:10:33.352" level="FAIL">No keyword with name 'When Launch application' found.</msg>
<status status="FAIL" starttime="20210802 17:10:33.352" endtime="20210802 17:10:33.352"/>
</kw>
<kw name="And Validate title">
<arg>Login</arg>
<status status="NOT RUN" starttime="20210802 17:10:33.354" endtime="20210802 17:10:33.354"/>
</kw>
<kw name="Then User is on login page">
<status status="NOT RUN" starttime="20210802 17:10:33.356" endtime="20210802 17:10:33.356"/>
</kw>
<status status="FAIL" starttime="20210802 17:10:33.349" endtime="20210802 17:10:33.356">No keyword with name 'When Launch application' found.</status>
</test>
<kw name="Close all screens" type="TEARDOWN">
<msg timestamp="20210802 17:10:33.358" level="FAIL">No keyword with name 'Close all screens' found.</msg>
<status status="FAIL" starttime="20210802 17:10:33.358" endtime="20210802 17:10:33.358">No keyword with name 'Close all screens' found.</status>
</kw>
<doc>This test suite contains app tests for the login page</doc>
<status status="FAIL" starttime="20210802 17:10:26.776" endtime="20210802 17:10:33.358">Suite teardown failed:
No keyword with name 'Close all screens' found.</status>
</suite>
<statistics>
<total>
<stat pass="0" fail="1" skip="0">All Tests</stat>
</total>
<tag>
</tag>
<suite>
<stat pass="0" fail="1" skip="0" id="s1" name="Login">Login</stat>
</suite>
</statistics>
<errors>
<msg timestamp="20210802 17:10:30.396" level="ERROR">Error in file '/Users/oa1220/Documents/Projects/appium-framework/app/tests/login.robot' on line 4: Importing library '/Users/oa1220/Documents/Projects/appium-framework/app/keywords/common.py' failed: WebDriverException: Message: An unknown server-side error occurred while processing the command. Original error: Could not proxy command to the remote server. Original error: socket hang up

Traceback (most recent call last):
  File "/Users/oa1220/Documents/Projects/appium-framework/app/keywords/common.py", line 7, in &lt;module&gt;
    bp = BasePage()
  File "/Users/oa1220/Documents/Projects/appium-framework/app/tests/../../framework/utils/base_page.py", line 18, in __init__
    self.driver = clients.getMobileDriver()
  File "/Users/oa1220/Documents/Projects/appium-framework/app/tests/../../framework/config/clients.py", line 10, in getMobileDriver
    driver = createDriver()
  File "/Users/oa1220/Documents/Projects/appium-framework/app/tests/../../framework/config/clients.py", line 34, in createDriver
    driver = webdriver.Remote("http://0.0.0.0:4723/wd/hub", desired_caps)
  File "/Users/oa1220/Documents/Projects/appium-framework/venv/lib/python3.8/site-packages/appium/webdriver/webdriver.py", line 155, in __init__
    super().__init__(
  File "/Users/oa1220/Documents/Projects/appium-framework/venv/lib/python3.8/site-packages/selenium/webdriver/remote/webdriver.py", line 157, in __init__
    self.start_session(capabilities, browser_profile)
  File "/Users/oa1220/Documents/Projects/appium-framework/venv/lib/python3.8/site-packages/appium/webdriver/webdriver.py", line 225, in start_session
    response = self.execute(RemoteCommand.NEW_SESSION, parameters)
  File "/Users/oa1220/Documents/Projects/appium-framework/venv/lib/python3.8/site-packages/selenium/webdriver/remote/webdriver.py", line 321, in execute
    self.error_handler.check_response(response)
  File "/Users/oa1220/Documents/Projects/appium-framework/venv/lib/python3.8/site-packages/selenium/webdriver/remote/errorhandler.py", line 242, in check_response
    raise exception_class(message, screen, stacktrace)
PYTHONPATH:
  /Users/oa1220/Documents/Projects/appium-framework/venv/bin
  /Library/Developer/CommandLineTools/Library/Frameworks/Python3.framework/Versions/3.8/lib/python38.zip
  /Library/Developer/CommandLineTools/Library/Frameworks/Python3.framework/Versions/3.8/lib/python3.8
  /Library/Developer/CommandLineTools/Library/Frameworks/Python3.framework/Versions/3.8/lib/python3.8/lib-dynload
  /Users/oa1220/Documents/Projects/appium-framework/venv/lib/python3.8/site-packages
  /Users/oa1220/Documents/Projects/appium-framework/app/tests/../..</msg>
<msg timestamp="20210802 17:10:33.348" level="ERROR">Error in file '/Users/oa1220/Documents/Projects/appium-framework/app/tests/login.robot' on line 5: Importing library '/Users/oa1220/Documents/Projects/appium-framework/app/keywords/login.py' failed: WebDriverException: Message: An unknown server-side error occurred while processing the command. Original error: Could not proxy command to the remote server. Original error: socket hang up

Traceback (most recent call last):
  File "/Users/oa1220/Documents/Projects/appium-framework/app/keywords/login.py", line 7, in &lt;module&gt;
    login = LoginScreen()
  File "/Users/oa1220/Documents/Projects/appium-framework/app/tests/../../app/pages/login_page.py", line 7, in __init__
    super().__init__()
  File "/Users/oa1220/Documents/Projects/appium-framework/app/tests/../../framework/utils/base_page.py", line 18, in __init__
    self.driver = clients.getMobileDriver()
  File "/Users/oa1220/Documents/Projects/appium-framework/app/tests/../../framework/config/clients.py", line 10, in getMobileDriver
    driver = createDriver()
  File "/Users/oa1220/Documents/Projects/appium-framework/app/tests/../../framework/config/clients.py", line 34, in createDriver
    driver = webdriver.Remote("http://0.0.0.0:4723/wd/hub", desired_caps)
  File "/Users/oa1220/Documents/Projects/appium-framework/venv/lib/python3.8/site-packages/appium/webdriver/webdriver.py", line 155, in __init__
    super().__init__(
  File "/Users/oa1220/Documents/Projects/appium-framework/venv/lib/python3.8/site-packages/selenium/webdriver/remote/webdriver.py", line 157, in __init__
    self.start_session(capabilities, browser_profile)
  File "/Users/oa1220/Documents/Projects/appium-framework/venv/lib/python3.8/site-packages/appium/webdriver/webdriver.py", line 225, in start_session
    response = self.execute(RemoteCommand.NEW_SESSION, parameters)
  File "/Users/oa1220/Documents/Projects/appium-framework/venv/lib/python3.8/site-packages/selenium/webdriver/remote/webdriver.py", line 321, in execute
    self.error_handler.check_response(response)
  File "/Users/oa1220/Documents/Projects/appium-framework/venv/lib/python3.8/site-packages/selenium/webdriver/remote/errorhandler.py", line 242, in check_response
    raise exception_class(message, screen, stacktrace)
PYTHONPATH:
  /Users/oa1220/Documents/Projects/appium-framework/venv/bin
  /Library/Developer/CommandLineTools/Library/Frameworks/Python3.framework/Versions/3.8/lib/python38.zip
  /Library/Developer/CommandLineTools/Library/Frameworks/Python3.framework/Versions/3.8/lib/python3.8
  /Library/Developer/CommandLineTools/Library/Frameworks/Python3.framework/Versions/3.8/lib/python3.8/lib-dynload
  /Users/oa1220/Documents/Projects/appium-framework/venv/lib/python3.8/site-packages
  /Users/oa1220/Documents/Projects/appium-framework/app/tests/../..
  /Users/oa1220/Documents/Projects/appium-framework/app/tests/../..</msg>
</errors>
</robot>
